Workbook

Sheet BD LP
B1: 1 | C1: 2 | D1: 3 | E1: 4 | F1: 5 | G1: 6 | H1: 7 | I1: 8 | J1: 9 | K1: 10 | M1: 11 | N1: 12 | O1: 13 | P1: 14 | Q1: 15 | R1: 16 | S1: 17 | T1: 18 | U1: 19 | V1: 20 | W1: 21 | X1: 22 | Y1: 23 | Z1: 24 | AA1: 25 | AB1: 26 | AC1: 27 | AD1: 28 | AE1: 29 | AF1: 30 | AH1: 32 | AI1: 33 | AJ1: 34
A2: BASE | B2: CÓDIGO | C2: - | D2: FS00 | E2: CATEGORY | F2: JEFE CATEGORÍA | G2: CATEGORÍA | H2: FAMILIA | I2: DESCRIPCIÓN | J2: UMV | K2: UMB | L2: UM Tipo Comercio | M2: DESCRIPCION UMV | N2: T° | O2: ORIGEN | P2: COSTO OCT | Q2: ESTADO OCT | R2: PRECIO OCT | S2: Dif. COSTOS MESES | T2: CAT. MANUAL al 27-10 | U2: S. PROPUESTO LP NOV | V2: COSTO OCT AL 27-10 | W2: COSTO | X2: DIF EN COSTOS MES | Y2: ESTADO | Z2: PRECIO | AA2: DIFERENCIAS | AB2: %MG UMV | AC2: MARGEN UNITARIO | AD2: Peso Neto UMV (KG) | AE2: Contribución x KG | AF2: VENTA X UNIDAD | AG2: VENTA X COMERCIO | AH2: D. AUTÓNOMO | AI2: DA MEDIOCAMPO | AJ2: PRODUCTO FOCO | AK2: LP PERSONAL
A3: EXCLUSIVOS | B3: 101600020 | C3: =+MaestraLP3[[#This Row],[CÓDIGO]]&MaestraLP3[[#Headers],[-]]&MaestraLP3[[#This Row],[UMV]] -> 101600020-C12 | D3: =+MaestraLP3[[#This Row],[CÓDIGO]]&MaestraLP3[[#Headers],[FS00]] -> 101600020FS00 | E3: BELTRÁN FRANZANI | F3: CAMILA UGARTE | G3: CAFE Y DERIVADOS | H3: CAFES DE GRANO MOLIDO | I3: CAFE CREMA E GUSTO TARRO LAVAZZA 250 g | J3: C12 | K3: UN | M3: =VLOOKUP(MaestraLP3[[#This Row],[UMV]],VALIDACIONES!J:L,3,0) -> Caja 12 Unidades | N3: SECO | O3: NFS | P3: 31946 | Q3: MANTIENE | R3: 117000 | S3: =IFERROR((MaestraLP3[[#This Row],[COSTO ]]/MaestraLP3[[#This Row],[COSTO OCT]]-1),0) -> 0 | T3: ACTIVO | V3: =+VLOOKUP(MaestraLP3[[#This Row],[-]],'[1]BD MES'!$A:$N,14,0) -> 31947 | W3: 31946 | X3: =+(MaestraLP3[[#This Row],[COSTO ]]-MaestraLP3[[#This Row],[COSTO OCT AL 27-10]])/MaestraLP3[[#This Row],[COSTO OCT AL 27-10]] -> -3.1301844e-05 | Y3: =++IF(Q3="HASTA AGOTAR STOCK","HASTA AGOTAR STOCK",IF(MaestraLP3[[#This Row],[PRECIO OCT]]=0,"NO PARA LP",IF(MaestraLP3[[#This Row],[PRECIO OCT]]=0,"INCORPORACIÓN",IF(AA3=0,"MANTIENE",IF(AA3<0,"BAJA",IF(AA3>0,"ALZA","")))))) -> MANTIENE | Z3: 117000 | AA3: =IF(Z3=0,"INDICAR PRECIO VTA",Z3-MaestraLP3[[#This Row],[PRECIO OCT]]) -> 0 | AB3: =+IFERROR((Z3-W3)/Z3,"-") -> 0.72695726 | AC3: =IFERROR(MaestraLP3[[#This Row],[PRECIO]]*MaestraLP3[[#This Row],[%MG UMV]],0) -> 85054 | AD3: 3 | AE3: =IFERROR(MaestraLP3[[#This Row],[MARGEN UNITARIO]]/MaestraLP3[[#This Row],[Peso Neto UMV (KG)]],0) -> 28351.333 | AF3: NO | AG3: 1 | AH3: 0.1 | AI3: 0 | AJ3: SI | AK3: NO
A4: EXCLUSIVOS | B4: 101600051 | C4: =+MaestraLP3[[#This Row],[CÓDIGO]]&MaestraLP3[[#Headers],[-]]&MaestraLP3[[#This Row],[UMV]] -> 101600051-C12 | D4: =+MaestraLP3[[#This Row],[CÓDIGO]]&MaestraLP3[[#Headers],[FS00]] -> 101600051FS00 | E4: BELTRÁN FRANZANI | F4: CAMILA UGARTE | G4: CAFE Y DERIVADOS | H4: CAFES DE GRANO MOLIDO | I4: CAFÉ DESCAFEINADO LAVAZZA 250 g | J4: C12 | K4: UN | M4: =VLOOKUP(MaestraLP3[[#This Row],[UMV]],VALIDACIONES!J:L,3,0) -> Caja 12 Unidades | N4: SECO | O4: NFS | P4: 57642.25 | Q4: MANTIENE | R4: 121500 | S4: =IFERROR((MaestraLP3[[#This Row],[COSTO ]]/MaestraLP3[[#This Row],[COSTO OCT]]-1),0) -> -0.065644211 | T4: ACTIVO | V4: =+VLOOKUP(MaestraLP3[[#This Row],[-]],'[1]BD MES'!$A:$N,14,0) -> 52836.93 | W4: 53858.37 | X4: =+(MaestraLP3[[#This Row],[COSTO ]]-MaestraLP3[[#This Row],[COSTO OCT AL 27-10]])/MaestraLP3[[#This Row],[COSTO OCT AL 27-10]] -> 0.019331933 | Y4: =++IF(Q4="HASTA AGOTAR STOCK","HASTA AGOTAR STOCK",IF(MaestraLP3[[#This Row],[PRECIO OCT]]=0,"NO PARA LP",IF(MaestraLP3[[#This Row],[PRECIO OCT]]=0,"INCORPORACIÓN",IF(AA4=0,"MANTIENE",IF(AA4<0,"BAJA",IF(AA4>0,"ALZA","")))))) -> MANTIENE | Z4: 121500 | AA4: =IF(Z4=0,"INDICAR PRECIO VTA",Z4-MaestraLP3[[#This Row],[PRECIO OCT]]) -> 0 | AB4: =+IFERROR((Z4-W4)/Z4,"-") -> 0.55672123 | AC4: =IFERROR(MaestraLP3[[#This Row],[PRECIO]]*MaestraLP3[[#This Row],[%MG UMV]],0) -> 67641.63 | AD4: 3 | AE4: =IFERROR(MaestraLP3[[#This Row],[MARGEN UNITARIO]]/MaestraLP3[[#This Row],[Peso Neto UMV (KG)]],0) -> 22547.21 | AF4: SI | AG4: 1 | AH4: 0.1 | AI4: 0 | AJ4: SI | AK4: NO
A5: EXCLUSIVOS | B5: 101600036 | C5: =+MaestraLP3[[#This Row],[CÓDIGO]]&MaestraLP3[[#Headers],[-]]&MaestraLP3[[#This Row],[UMV]] -> 101600036-C06 | D5: =+MaestraLP3[[#This Row],[CÓDIGO]]&MaestraLP3[[#Headers],[FS00]] -> 101600036FS00 | E5: BELTRÁN FRANZANI | F5: CAMILA UGARTE | G5: CAFE Y DERIVADOS | H5: CAFES DE GRANO MOLIDO | I5: CAFÉ MOLIDO TIERRA BIO 180 g | J5: C06 | K5: UN | M5: =VLOOKUP(MaestraLP3[[#This Row],[UMV]],VALIDACIONES!J:L,3,0) -> Caja 6 Unidades | N5: SECO | O5: NFS | P5: 24001 | Q5: MANTIENE | R5: 61998 | S5: =IFERROR((MaestraLP3[[#This Row],[COSTO ]]/MaestraLP3[[#This Row],[COSTO OCT]]-1),0) -> -0.05728428 | T5: ACTIVO | V5: =+VLOOKUP(MaestraLP3[[#This Row],[-]],'[1]BD MES'!$A:$N,14,0) -> 22626.5 | W5: 22626.12 | X5: =+(MaestraLP3[[#This Row],[COSTO ]]-MaestraLP3[[#This Row],[COSTO OCT AL 27-10]])/MaestraLP3[[#This Row],[COSTO OCT AL 27-10]] -> -1.6794467e-05 | Y5: =++IF(Q5="HASTA AGOTAR STOCK","HASTA AGOTAR STOCK",IF(MaestraLP3[[#This Row],[PRECIO OCT]]=0,"NO PARA LP",IF(MaestraLP3[[#This Row],[PRECIO OCT]]=0,"INCORPORACIÓN",IF(AA5=0,"MANTIENE",IF(AA5<0,"BAJA",IF(AA5>0,"ALZA","")))))) -> MANTIENE | Z5: 61998 | AA5: =IF(Z5=0,"INDICAR PRECIO VTA",Z5-MaestraLP3[[#This Row],[PRECIO OCT]]) -> 0 | AB5: =+IFERROR((Z5-W5)/Z5,"-") -> 0.63505081 | AC5: =IFERROR(MaestraLP3[[#This Row],[PRECIO]]*MaestraLP3[[#This Row],[%MG UMV]],0) -> 39371.88 | AD5: 1.08 | AE5: =IFERROR(MaestraLP3[[#This Row],[MARGEN UNITARIO]]/MaestraLP3[[#This Row],[Peso Neto UMV (KG)]],0) -> 36455.444 | AF5: SI | AG5: 1 | AH5: 0.1 | AI5: 0 | AK5: NO
A6: EXCLUSIVOS | B6: 101600038 | C6: =+MaestraLP3[[#This Row],[CÓDIGO]]&MaestraLP3[[#Headers],[-]]&MaestraLP3[[#This Row],[UMV]] -> 101600038-C06 | D6: =+MaestraLP3[[#This Row],[CÓDIGO]]&MaestraLP3[[#Headers],[FS00]] -> 101600038FS00 | E6: BELTRÁN FRANZANI | F6: CAMILA UGARTE | G6: CAFE Y DERIVADOS | H6: CAFES DE GRANO MOLIDO | I6: CAFÉ MOLIDO TIERRA FOR AFRICA 180g | J6: C06 | K6: UN | M6: =VLOOKUP(MaestraLP3[[#This Row],[UMV]],VALIDACIONES!J:L,3,0) -> Caja 6 Unidades | N6: SECO | O6: NFS | P6: 21646.39 | Q6: MANTIENE | R6: 61998 | S6: =IFERROR((MaestraLP3[[#This Row],[COSTO ]]/MaestraLP3[[#This Row],[COSTO OCT]]-1),0) -> -0.055910939 | T6: ACTIVO | V6: =+VLOOKUP(MaestraLP3[[#This Row],[-]],'[1]BD MES'!$A:$N,14,0) -> 20436.12 | W6: 20436.12 | X6: =+(MaestraLP3[[#This Row],[COSTO ]]-MaestraLP3[[#This Row],[COSTO OCT AL 27-10]])/MaestraLP3[[#This Row],[COSTO OCT AL 27-10]] -> 0 | Y6: =++IF(Q6="HASTA AGOTAR STOCK","HASTA AGOTAR STOCK",IF(MaestraLP3[[#This Row],[PRECIO OCT]]=0,"NO PARA LP",IF(MaestraLP3[[#This Row],[PRECIO OCT]]=0,"INCORPORACIÓN",IF(AA6=0,"MANTIENE",IF(AA6<0,"BAJA",IF(AA6>0,"ALZA","")))))) -> MANTIENE | Z6: 61998 | AA6: =IF(Z6=0,"INDICAR PRECIO VTA",Z6-MaestraLP3[[#This Row],[PRECIO OCT]]) -> 0 | AB6: =+IFERROR((Z6-W6)/Z6,"-") -> 0.67037453 | AC6: =IFERROR(MaestraLP3[[#This Row],[PRECIO]]*MaestraLP3[[#This Row],[%MG UMV]],0) -> 41561.88 | AD6: 1.08 | AE6: =IFERROR(MaestraLP3[[#This Row],[MARGEN UNITARIO]]/MaestraLP3[[#This Row],[Peso Neto UMV (KG)]],0) -> 38483.222 | AF6: SI | AG6: 1 | AH6: 0.1 | AI6: 0 | AK6: NO
A7: EXCLUSIVOS | B7: 101600062 | C7: =+MaestraLP3[[#This Row],[CÓDIGO]]&MaestraLP3[[#Headers],[-]]&MaestraLP3[[#This Row],[UMV]] -> 101600062-C06 | D7: =+MaestraLP3[[#This Row],[CÓDIGO]]&MaestraLP3[[#Headers],[FS00]] -> 101600062FS00 | E7: BELTRÁN FRANZANI | F7: CAMILA UGARTE | G7: CAFE Y DERIVADOS | H7: CAFES DE GRANO MOLIDO | I7: CAFÉ MOLIDO TIERRA FOR CUBA 180g | J7: C06 | K7: UN | M7: =VLOOKUP(MaestraLP3[[#This Row],[UMV]],VALIDACIONES!J:L,3,0) -> Caja 6 Unidades | N7: SECO | O7: NFS | P7: 15990.86 | Q7: MANTIENE | R7: 61998 | S7: =IFERROR((MaestraLP3[[#This Row],[COSTO ]]/MaestraLP3[[#This Row],[COSTO OCT]]-1),0) -> 8.7550013e-06 | T7: ACTIVO | V7: =+VLOOKUP(MaestraLP3[[#This Row],[-]],'[1]BD MES'!$A:$N,14,0) -> 15991 | W7: 15991 | X7: =+(MaestraLP3[[#This Row],[COSTO ]]-MaestraLP3[[#This Row],[COSTO OCT AL 27-10]])/MaestraLP3[[#This Row],[COSTO OCT AL 27-10]] -> 0 | Y7: =++IF(Q7="HASTA AGOTAR STOCK","HASTA AGOTAR STOCK",IF(MaestraLP3[[#This Row],[PRECIO OCT]]=0,"NO PARA LP",IF(MaestraLP3[[#This Row],[PRECIO OCT]]=0,"INCORPORACIÓN",IF(AA7=0,"MANTIENE",IF(AA7<0,"BAJA",IF(AA7>0,"ALZA","")))))) -> MANTIENE | Z7: 61998 | AA7: =IF(Z7=0,"INDICAR PRECIO VTA",Z7-MaestraLP3[[#This Row],[PRECIO OCT]]) -> 0 | AB7: =+IFERROR((Z7-W7)/Z7,"-") -> 0.74207232 | AC7: =IFERROR(MaestraLP3[[#This Row],[PRECIO]]*MaestraLP3[[#This Row],[%MG UMV]],0) -> 46007 | AD7: 1.08 | AE7: =IFERROR(MaestraLP3[[#This Row],[MARGEN UNITARIO]]/MaestraLP3[[#This Row],[Peso Neto UMV (KG)]],0) -> 42599.074 | AF7: SI | AG7: 1 | AH7: 0.1 | AI7: 0 | AK7: NO
A8: EXCLUSIVOS | B8: 101600070 | C8: =+MaestraLP3[[#This Row],[CÓDIGO]]&MaestraLP3[[#Headers],[-]]&MaestraLP3[[#This Row],[UMV]] -> 101600070-C06 | D8: =+MaestraLP3[[#This Row],[CÓDIGO]]&MaestraLP3[[#Headers],[FS00]] -> 101600070FS00 | E8: BELTRÁN FRANZANI | F8: CAMILA UGARTE | G8: CAFE Y DERIVADOS | H8: CAFES SOLUBLES | I8: CAFE PRONTISSIMO CLASI LATA LAVAZZA 95 g | J8: C06 | K8: UN | M8: =VLOOKUP(MaestraLP3[[#This Row],[UMV]],VALIDACIONES!J:L,3,0) -> Caja 6 Unidades | N8: SECO | O8: NFS | P8: 18598 | Q8: ALZA | R8: 39990 | S8: =IFERROR((MaestraLP3[[#This Row],[COSTO ]]/MaestraLP3[[#This Row],[COSTO OCT]]-1),0) -> 0.021077535 | T8: ACTIVO | V8: =+VLOOKUP(MaestraLP3[[#This Row],[-]],'[1]BD MES'!$A:$N,14,0) -> 18990 | W8: 18990 | X8: =+(MaestraLP3[[#This Row],[COSTO ]]-MaestraLP3[[#This Row],[COSTO OCT AL 27-10]])/MaestraLP3[[#This Row],[COSTO OCT AL 27-10]] -> 0 | Y8: =++IF(Q8="HASTA AGOTAR STOCK","HASTA AGOTAR STOCK",IF(MaestraLP3[[#This Row],[PRECIO OCT]]=0,"NO PARA LP",IF(MaestraLP3[[#This Row],[PRECIO OCT]]=0,"INCORPORACIÓN",IF(AA8=0,"MANTIENE",IF(AA8<0,"BAJA",IF(AA8>0,"ALZA","")))))) -> MANTIENE | Z8: 39990 | AA8: =IF(Z8=0,"INDICAR PRECIO VTA",Z8-MaestraLP3[[#This Row],[PRECIO OCT]]) -> 0 | AB8: =+IFERROR((Z8-W8)/Z8,"-") -> 0.52513128 | AC8: =IFERROR(MaestraLP3[[#This Row],[PRECIO]]*MaestraLP3[[#This Row],[%MG UMV]],0) -> 21000 | AD8: 0.57 | AE8: =IFERROR(MaestraLP3[[#This Row],[MARGEN UNITARIO]]/MaestraLP3[[#This Row],[Peso Neto UMV (KG)]],0) -> 36842.105 | AF8: NO | AG8: 1 | AH8: 0.1 | AI8: 0 | AJ8: SI | AK8: NO
A9: EXCLUSIVOS | B9: 101600041 | C9: =+MaestraLP3[[#This Row],[CÓDIGO]]&MaestraLP3[[#Headers],[-]]&MaestraLP3[[#This Row],[UMV]] -> 101600041-C10 | D9: =+MaestraLP3[[#This Row],[CÓDIGO]]&MaestraLP3[[#Headers],[FS00]] -> 101600041FS00 | E9: BELTRÁN FRANZANI | F9: CAMILA UGARTE | G9: CAFE Y DERIVADOS | H9: CAPSULAS Y PODS | I9: CAPSULA ESPRESSO CLASSICO LAVAZZA 57 g | J9: C10 | K9: UN | L9: UN | M9: =VLOOKUP(MaestraLP3[[#This Row],[UMV]],VALIDACIONES!J:L,3,0) -> Caja 10 Unidades | N9: SECO | O9: NFS | P9: 26822.2 | Q9: BAJA | R9: 41930 | S9: =IFERROR((MaestraLP3[[#This Row],[COSTO ]]/MaestraLP3[[#This Row],[COSTO OCT]]-1),0) -> 0.020664226 | T9: ACTIVO | V9: =+VLOOKUP(MaestraLP3[[#This Row],[-]],'[1]BD MES'!$A:$N,14,0) -> 27372.58 | W9: 27376.46 | X9: =+(MaestraLP3[[#This Row],[COSTO ]]-MaestraLP3[[#This Row],[COSTO OCT AL 27-10]])/MaestraLP3[[#This Row],[COSTO OCT AL 27-10]] -> 0.00014174769 | Y9: =++IF(Q9="HASTA AGOTAR STOCK","HASTA AGOTAR STOCK",IF(MaestraLP3[[#This Row],[PRECIO OCT]]=0,"NO PARA LP",IF(MaestraLP3[[#This Row],[PRECIO OCT]]=0,"INCORPORACIÓN",IF(AA9=0,"MANTIENE",IF(AA9<0,"BAJA",IF(AA9>0,"ALZA","")))))) -> MANTIENE | Z9: 41930 | AA9: =IF(Z9=0,"INDICAR PRECIO VTA",Z9-MaestraLP3[[#This Row],[PRECIO OCT]]) -> 0 | AB9: =+IFERROR((Z9-W9)/Z9,"-") -> 0.34709134 | AC9: =IFERROR(MaestraLP3[[#This Row],[PRECIO]]*MaestraLP3[[#This Row],[%MG UMV]],0) -> 14553.54 | AD9: 0.57 | AE9: =IFERROR(MaestraLP3[[#This Row],[MARGEN UNITARIO]]/MaestraLP3[[#This Row],[Peso Neto UMV (KG)]],0) -> 25532.526 | AF9: NO | AG9: 2 y 3 | AH9: 0.1 | AI9: 0 | AJ9: SI | AK9: NO
A10: EXCLUSIVOS | B10: 101600042 | C10: =+MaestraLP3[[#This Row],[CÓDIGO]]&MaestraLP3[[#Headers],[-]]&MaestraLP3[[#This Row],[UMV]] -> 101600042-C10 | D10: =+MaestraLP3[[#This Row],[CÓDIGO]]&MaestraLP3[[#Headers],[FS00]] -> 101600042FS00 | E10: BELTRÁN FRANZANI | F10: CAMILA UGARTE | G10: CAFE Y DERIVADOS | H10: CAPSULAS Y PODS | I10: CAPSULA ESPRESSO INTENSO LAVAZZA 57 g | J10: C10 | K10: UN | L10: UN | M10: =VLOOKUP(MaestraLP3[[#This Row],[UMV]],VALIDACIONES!J:L,3,0) -> Caja 10 Unidades | N10: SECO | O10: NFS | P10: 22229 | Q10: BAJA | R10: 41930 | S10: =IFERROR((MaestraLP3[[#This Row],[COSTO ]]/MaestraLP3[[#This Row],[COSTO OCT]]-1),0) -> 0.25466733 | T10: ACTIVO | V10: =+VLOOKUP(MaestraLP3[[#This Row],[-]],'[1]BD MES'!$A:$N,14,0) -> 27713.98 | W10: 27890 | X10: =+(MaestraLP3[[#This Row],[COSTO ]]-MaestraLP3[[#This Row],[COSTO OCT AL 27-10]])/MaestraLP3[[#This Row],[COSTO OCT AL 27-10]] -> 0.0063513072 | Y10: =++IF(Q10="HASTA AGOTAR STOCK","HASTA AGOTAR STOCK",IF(MaestraLP3[[#This Row],[PRECIO OCT]]=0,"NO PARA LP",IF(MaestraLP3[[#This Row],[PRECIO OCT]]=0,"INCORPORACIÓN",IF(AA10=0,"MANTIENE",IF(AA10<0,"BAJA",IF(AA10>0,"ALZA","")))))) -> MANTIENE | Z10: 41930 | AA10: =IF(Z10=0,"INDICAR PRECIO VTA",Z10-MaestraLP3[[#This Row],[PRECIO OCT]]) -> 0 | AB10: =+IFERROR((Z10-W10)/Z10,"-") -> 0.33484379 | AC10: =IFERROR(MaestraLP3[[#This Row],[PRECIO]]*MaestraLP3[[#This Row],[%MG UMV]],0) -> 14040 | AD10: 0.53 | AE10: =IFERROR(MaestraLP3[[#This Row],[MARGEN UNITARIO]]/MaestraLP3[[#This Row],[Peso Neto UMV (KG)]],0) -> 26490.566 | AF10: NO | AG10: 2 y 3 | AH10: 0.1 | AI10: 0 | AJ10: SI | AK10: NO
A11: EXCLUSIVOS | B11: 101600043 | C11: =+MaestraLP3[[#This Row],[CÓDIGO]]&MaestraLP3[[#Headers],[-]]&MaestraLP3[[#This Row],[UMV]] -> 101600043-C10 | D11: =+MaestraLP3[[#This Row],[CÓDIGO]]&MaestraLP3[[#Headers],[FS00]] -> 101600043FS00 | E11: BELTRÁN FRANZANI | F11: CAMILA UGARTE | G11: CAFE Y DERIVADOS | H11: CAPSULAS Y PODS | I11: CAPSULA ESPRESSO QUALITA ORO LAVAZZA 55g | J11: C10 | K11: UN | L11: UN | M11: =VLOOKUP(MaestraLP3[[#This Row],[UMV]],VALIDACIONES!J:L,3,0) -> Caja 10 Unidades | N11: SECO | O11: NFS | P11: 25549.45 | Q11: BAJA | R11: 41930 | S11: =IFERROR((MaestraLP3[[#This Row],[COSTO ]]/MaestraLP3[[#This Row],[COSTO OCT]]-1),0) -> 0.017007803 | T11: ACTIVO | V11: =+VLOOKUP(MaestraLP3[[#This Row],[-]],'[1]BD MES'!$A:$N,14,0) -> 27446.33 | W11: 25983.99 | X11: =+(MaestraLP3[[#This Row],[COSTO ]]-MaestraLP3[[#This Row],[COSTO OCT AL 27-10]])/MaestraLP3[[#This Row],[COSTO OCT AL 27-10]] -> -0.053279983 | Y11: =++IF(Q11="HASTA AGOTAR STOCK","HASTA AGOTAR STOCK",IF(MaestraLP3[[#This Row],[PRECIO OCT]]=0,"NO PARA LP",IF(MaestraLP3[[#This Row],[PRECIO OCT]]=0,"INCORPORACIÓN",IF(AA11=0,"MANTIENE",IF(AA11<0,"BAJA",IF(AA11>0,"ALZA","")))))) -> MANTIENE | Z11: 41930 | AA11: =IF(Z11=0,"INDICAR PRECIO VTA",Z11-MaestraLP3[[#This Row],[PRECIO OCT]]) -> 0 | AB11: =+IFERROR((Z11-W11)/Z11,"-") -> 0.38030074 | AC11: =IFERROR(MaestraLP3[[#This Row],[PRECIO]]*MaestraLP3[[#This Row],[%MG UMV]],0) -> 15946.01 | AD11: 0.55 | AE11: =IFERROR(MaestraLP3[[#This Row],[MARGEN UNITARIO]]/MaestraLP3[[#This Row],[Peso Neto UMV (KG)]],0) -> 28992.745 | AF11: NO | AG11: 2 y 3 | AH11: 0.1 | AI11: 0 | AJ11: SI | AK11: NO
A12: EXCLUSIVOS | B12: 104543140 | C12: =+MaestraLP3[[#This Row],[CÓDIGO]]&MaestraLP3[[#Headers],[-]]&MaestraLP3[[#This Row],[UMV]] -> 104543140-Z50 | D12: =+MaestraLP3[[#This Row],[CÓDIGO]]&MaestraLP3[[#Headers],[FS00]] -> 104543140FS00 | E12: BERNARDITA UNDURRAGA | F12: BERNARDITA UNDURRAGA | G12: BOLLERIA | H12: BOLLERIA PARA HORNEAR | I12: GALLETA CHOCOLATE HILTON 63,78 G | J12: Z50 | K12: Z50 | M12: =VLOOKUP(MaestraLP3[[#This Row],[UMV]],VALIDACIONES!J:L,3,0) -> Caja 150 Unidades | N12: CONGELADOS | O12: IFS | P12: 85543 | Q12: NO PARA LP | R12: 0 | S12: =IFERROR((MaestraLP3[[#This Row],[COSTO ]]/MaestraLP3[[#This Row],[COSTO OCT]]-1),0) -> 0 | T12: CALZADA | U12: CALZADA | V12: =+VLOOKUP(MaestraLP3[[#This Row],[-]],'[1]BD MES'!$A:$N,14,0) -> 75270 | W12: 85543 | X12: =+(MaestraLP3[[#This Row],[COSTO ]]-MaestraLP3[[#This Row],[COSTO OCT AL 27-10]])/MaestraLP3[[#This Row],[COSTO OCT AL 27-10]] -> 0.136482 | Y12: =++IF(Q12="HASTA AGOTAR STOCK","HASTA AGOTAR STOCK",IF(MaestraLP3[[#This Row],[PRECIO OCT]]=0,"NO PARA LP",IF(MaestraLP3[[#This Row],[PRECIO OCT]]=0,"INCORPORACIÓN",IF(AA12=0,"MANTIENE",IF(AA12<0,"BAJA",IF(AA12>0,"ALZA","")))))) -> NO PARA LP | AA12: =IF(Z12=0,"INDICAR PRECIO VTA",Z12-MaestraLP3[[#This Row],[PRECIO OCT]]) -> INDICAR PRECIO VTA | AB12: =+IFERROR((Z12-W12)/Z12,"-") -> - | AC12: =IFERROR(MaestraLP3[[#This Row],[PRECIO]]*MaestraLP3[[#This Row],[%MG UMV]],0) -> 0 | AD12: 9.56 | AE12: =IFERROR(MaestraLP3[[#This Row],[MARGEN UNITARIO]]/MaestraLP3[[#This Row],[Peso Neto UMV (KG)]],0) -> 0 | AF12: NO | AG12: 1 | AH12: 0.05 | AI12: 0.05 | AK12: NO
A13: EXCLUSIVOS | B13: 104548580 | C13: =+MaestraLP3[[#This Row],[CÓDIGO]]&MaestraLP3[[#Headers],[-]]&MaestraLP3[[#This Row],[UMV]] -> 104548580-UN | D13: =+MaestraLP3[[#This Row],[CÓDIGO]]&MaestraLP3[[#Headers],[FS00]] -> 104548580FS00 | E13: BERNARDITA UNDURRAGA | F13: BERNARDITA UNDURRAGA | G13: BOLLERIA | H13: BOLLERIA PARA HORNEAR | I13: MINI CROISSANT 35 G | J13: UN | K13: UN | M13: =VLOOKUP(MaestraLP3[[#This Row],[UMV]],VALIDACIONES!J:L,3,0) -> Unidad | N13: CONGELADOS | O13: IFS | P13: 96 | Q13: NO PARA LP | R13: 0 | S13: =IFERROR((MaestraLP3[[#This Row],[COSTO ]]/MaestraLP3[[#This Row],[COSTO OCT]]-1),0) -> 0 | T13: CALZADA | U13: CALZADA | V13: =+VLOOKUP(MaestraLP3[[#This Row],[-]],'[1]BD MES'!$A:$N,14,0) -> 95 | W13: 96 | X13: =+(MaestraLP3[[#This Row],[COSTO ]]-MaestraLP3[[#This Row],[COSTO OCT AL 27-10]])/MaestraLP3[[#This Row],[COSTO OCT AL 27-10]] -> 0.010526316 | Y13: =++IF(Q13="HASTA AGOTAR STOCK","HASTA AGOTAR STOCK",IF(MaestraLP3[[#This Row],[PRECIO OCT]]=0,"NO PARA LP",IF(MaestraLP3[[#This Row],[PRECIO OCT]]=0,"INCORPORACIÓN",IF(AA13=0,"MANTIENE",IF(AA13<0,"BAJA",IF(AA13>0,"ALZA","")))))) -> NO PARA LP | Z13: 0 | AA13: =IF(Z13=0,"INDICAR PRECIO VTA",Z13-MaestraLP3[[#This Row],[PRECIO OCT]]) -> INDICAR PRECIO VTA | AB13: =+IFERROR((Z13-W13)/Z13,"-") -> - | AC13: =IFERROR(MaestraLP3[[#This Row],[PRECIO]]*MaestraLP3[[#This Row],[%MG UMV]],0) -> 0 | AD13: 0.04 | AE13: =IFERROR(MaestraLP3[[#This Row],[MARGEN UNITARIO]]/MaestraLP3[[#This Row],[Peso Neto UMV (KG)]],0) -> 0 | AF13: NO | AG13: 1 | AH13: 0 | AI13: 0 | AK13: NO
A14: EXCLUSIVOS | B14: 104544050 | C14: =+MaestraLP3[[#This Row],[CÓDIGO]]&MaestraLP3[[#Headers],[-]]&MaestraLP3[[#This Row],[UMV]] -> 104544050-CJ | D14: =+MaestraLP3[[#This Row],[CÓDIGO]]&MaestraLP3[[#Headers],[FS00]] -> 104544050FS00 | E14: BERNARDITA UNDURRAGA | F14: BERNARDITA UNDURRAGA | G14: BOLLERIA | H14: BOLLERIA PARA HORNEAR | I14: MINI CROISSANT RECTO 5 KG | J14: CJ | K14: CJ | M14: =VLOOKUP(MaestraLP3[[#This Row],[UMV]],VALIDACIONES!J:L,3,0) -> Caja | N14: CONGELADOS | O14: IFS | P14: 22773 | Q14: NO PARA LP | R14: 0 | S14: =IFERROR((MaestraLP3[[#This Row],[COSTO ]]/MaestraLP3[[#This Row],[COSTO OCT]]-1),0) -> 0 | T14: CALZADA | U14: CALZADA | V14: =+VLOOKUP(MaestraLP3[[#This Row],[-]],'[1]BD MES'!$A:$N,14,0) -> 22773 | W14: 22773 | X14: =+(MaestraLP3[[#This Row],[COSTO ]]-MaestraLP3[[#This Row],[COSTO OCT AL 27-10]])/MaestraLP3[[#This Row],[COSTO OCT AL 27-10]] -> 0 | Y14: =++IF(Q14="HASTA AGOTAR STOCK","HASTA AGOTAR STOCK",IF(MaestraLP3[[#This Row],[PRECIO OCT]]=0,"NO PARA LP",IF(MaestraLP3[[#This Row],[PRECIO OCT]]=0,"INCORPORACIÓN",IF(AA14=0,"MANTIENE",IF(AA14<0,"BAJA",IF(AA14>0,"ALZA","")))))) -> NO PARA LP | Z14: 0 | AA14: =IF(Z14=0,"INDICAR PRECIO VTA",Z14-MaestraLP3[[#This Row],[PRECIO OCT]]) -> INDICAR PRECIO VTA | AB14: =+IFERROR((Z14-W14)/Z14,"-") -> - | AC14: =IFERROR(MaestraLP3[[#This Row],[PRECIO]]*MaestraLP3[[#This Row],[%MG UMV]],0) -> 0 | AD14: 5 | AE14: =IFERROR(MaestraLP3[[#This Row],[MARGEN UNITARIO]]/MaestraLP3[[#This Row],[Peso Neto UMV (KG)]],0) -> 0 | AF14: NO | AG14: 1 | AH14: 0 | AI14: 0 | AK14: NO
A15: EXCLUSIVOS | B15: 104544060 | C15: =+MaestraLP3[[#This Row],[CÓDIGO]]&MaestraLP3[[#Headers],[-]]&MaestraLP3[[#This Row],[UMV]] -> 104544060-CJ | D15: =+MaestraLP3[[#This Row],[CÓDIGO]]&MaestraLP3[[#Headers],[FS00]] -> 104544060FS00 | E15: BERNARDITA UNDURRAGA | F15: BERNARDITA UNDURRAGA | G15: BOLLERIA | H15: BOLLERIA PARA HORNEAR | I15: PALMERA MINI 5 KG | J15: CJ | K15: CJ | M15: =VLOOKUP(MaestraLP3[[#This Row],[UMV]],VALIDACIONES!J:L,3,0) -> Caja | N15: CONGELADOS | O15: IFS | P15: 24051 | Q15: NO PARA LP | R15: 0 | S15: =IFERROR((MaestraLP3[[#This Row],[COSTO ]]/MaestraLP3[[#This Row],[COSTO OCT]]-1),0) -> 0 | T15: CALZADA | U15: CALZADA | V15: =+VLOOKUP(MaestraLP3[[#This Row],[-]],'[1]BD MES'!$A:$N,14,0) -> 24051 | W15: 24051 | X15: =+(MaestraLP3[[#This Row],[COSTO ]]-MaestraLP3[[#This Row],[COSTO OCT AL 27-10]])/MaestraLP3[[#This Row],[COSTO OCT AL 27-10]] -> 0 | Y15: =++IF(Q15="HASTA AGOTAR STOCK","HASTA AGOTAR STOCK",IF(MaestraLP3[[#This Row],[PRECIO OCT]]=0,"NO PARA LP",IF(MaestraLP3[[#This Row],[PRECIO OCT]]=0,"INCORPORACIÓN",IF(AA15=0,"MANTIENE",IF(AA15<0,"BAJA",IF(AA15>0,"ALZA","")))))) -> NO PARA LP | Z15: 0 | AA15: =IF(Z15=0,"INDICAR PRECIO VTA",Z15-MaestraLP3[[#This Row],[PRECIO OCT]]) -> INDICAR PRECIO VTA | AB15: =+IFERROR((Z15-W15)/Z15,"-") -> - | AC15: =IFERROR(MaestraLP3[[#This Row],[PRECIO]]*MaestraLP3[[#This Row],[%MG UMV]],0) -> 0 | AD15: 5 | AE15: =IFERROR(MaestraLP3[[#This Row],[MARGEN UNITARIO]]/MaestraLP3[[#This Row],[Peso Neto UMV (KG)]],0) -> 0 | AF15: NO | AG15: 1 | AH15: 0 | AI15: 0 | AK15: NO
A16: EXCLUSIVOS | B16: 104548600 | C16: =+MaestraLP3[[#This Row],[CÓDIGO]]&MaestraLP3[[#Headers],[-]]&MaestraLP3[[#This Row],[UMV]] -> 104548600-UN | D16: =+MaestraLP3[[#This Row],[CÓDIGO]]&MaestraLP3[[#Headers],[FS00]] -> 104548600FS00 | E16: BERNARDITA UNDURRAGA | F16: BERNARDITA UNDURRAGA | G16: BOLLERIA | H16: BOLLERIA PARA HORNEAR | I16: PALMERITA 23 G | J16: UN | K16: UN | M16: =VLOOKUP(MaestraLP3[[#This Row],[UMV]],VALIDACIONES!J:L,3,0) -> Unidad | N16: CONGELADOS | O16: IFS | P16: 69 | Q16: NO PARA LP | R16: 0 | S16: =IFERROR((MaestraLP3[[#This Row],[COSTO ]]/MaestraLP3[[#This Row],[COSTO OCT]]-1),0) -> 0 | T16: CALZADA | U16: CALZADA | V16: =+VLOOKUP(MaestraLP3[[#This Row],[-]],'[1]BD MES'!$A:$N,14,0) -> 71 | W16: 69 | X16: =+(MaestraLP3[[#This Row],[COSTO ]]-MaestraLP3[[#This Row],[COSTO OCT AL 27-10]])/MaestraLP3[[#This Row],[COSTO OCT AL 27-10]] -> -0.028169014 | Y16: =++IF(Q16="HASTA AGOTAR STOCK","HASTA AGOTAR STOCK",IF(MaestraLP3[[#This Row],[PRECIO OCT]]=0,"NO PARA LP",IF(MaestraLP3[[#This Row],[PRECIO OCT]]=0,"INCORPORACIÓN",IF(AA16=0,"MANTIENE",IF(AA16<0,"BAJA",IF(AA16>0,"ALZA","")))))) -> NO PARA LP | Z16: 0 | AA16: =IF(Z16=0,"INDICAR PRECIO VTA",Z16-MaestraLP3[[#This Row],[PRECIO OCT]]) -> INDICAR PRECIO VTA | AB16: =+IFERROR((Z16-W16)/Z16,"-") -> - | AC16: =IFERROR(MaestraLP3[[#This Row],[PRECIO]]*MaestraLP3[[#This Row],[%MG UMV]],0) -> 0 | AD16: 0.02 | AE16: =IFERROR(MaestraLP3[[#This Row],[MARGEN UNITARIO]]/MaestraLP3[[#This Row],[Peso Neto UMV (KG)]],0) -> 0 | AF16: NO | AG16: 1 | AH16: 0 | AI16: 0 | AK16: NO
A17: EXCLUSIVOS | B17: 104548530 | C17: =+MaestraLP3[[#This Row],[CÓDIGO]]&MaestraLP3[[#Headers],[-]]&MaestraLP3[[#This Row],[UMV]] -> 104548530-C60 | D17: =+MaestraLP3[[#This Row],[CÓDIGO]]&MaestraLP3[[#Headers],[FS00]] -> 104548530FS00 | E17: BERNARDITA UNDURRAGA | F17: BERNARDITA UNDURRAGA | G17: BOLLERIA | H17: BOLLERIA PARA HORNEAR | I17: ROLLITO DE CHOCOLATE 80 G | J17: C60 | K17: UN | M17: =VLOOKUP(MaestraLP3[[#This Row],[UMV]],VALIDACIONES!J:L,3,0) -> Caja 60 Unidades | N17: CONGELADOS | O17: IFS | P17: 42660 | Q17: NO PARA LP | R17: 0 | S17: =IFERROR((MaestraLP3[[#This Row],[COSTO ]]/MaestraLP3[[#This Row],[COSTO OCT]]-1),0) -> 0 | T17: CALZADA | U17: CALZADA | V17: =+VLOOKUP(MaestraLP3[[#This Row],[-]],'[1]BD MES'!$A:$N,14,0) -> 46200 | W17: 42660 | X17: =+(MaestraLP3[[#This Row],[COSTO ]]-MaestraLP3[[#This Row],[COSTO OCT AL 27-10]])/MaestraLP3[[#This Row],[COSTO OCT AL 27-10]] -> -0.076623377 | Y17: =++IF(Q17="HASTA AGOTAR STOCK","HASTA AGOTAR STOCK",IF(MaestraLP3[[#This Row],[PRECIO OCT]]=0,"NO PARA LP",IF(MaestraLP3[[#This Row],[PRECIO OCT]]=0,"INCORPORACIÓN",IF(AA17=0,"MANTIENE",IF(AA17<0,"BAJA",IF(AA17>0,"ALZA","")))))) -> NO PARA LP | Z17: 0 | AA17: =IF(Z17=0,"INDICAR PRECIO VTA",Z17-MaestraLP3[[#This Row],[PRECIO OCT]]) -> INDICAR PRECIO VTA | AB17: =+IFERROR((Z17-W17)/Z17,"-") -> - | AC17: =IFERROR(MaestraLP3[[#This Row],[PRECIO]]*MaestraLP3[[#This Row],[%MG UMV]],0) -> 0 | AD17: 4.8 | AE17: =IFERROR(MaestraLP3[[#This Row],[MARGEN UNITARIO]]/MaestraLP3[[#This Row],[Peso Neto UMV (KG)]],0) -> 0 | AF17: NO | AG17: 1 | AH17: 0 | AI17: 0 | AK17: NO
A18: EXCLUSIVOS | B18: 104548520 | C18: =+MaestraLP3[[#This Row],[CÓDIGO]]&MaestraLP3[[#Headers],[-]]&MaestraLP3[[#This Row],[UMV]] -> 104548520-C31 | D18: =+MaestraLP3[[#This Row],[CÓDIGO]]&MaestraLP3[[#Headers],[FS00]] -> 104548520FS00 | E18: BERNARDITA UNDURRAGA | F18: BERNARDITA UNDURRAGA | G18: BOLLERIA | H18: PANES PARA HORNEAR | I18: PAN BAGUETTE GRANDE 260 G | J18: C31 | K18: UN | M18: =VLOOKUP(MaestraLP3[[#This Row],[UMV]],VALIDACIONES!J:L,3,0) -> Caja 31 Unidades | N18: CONGELADOS | O18: IFS | P18: 15190 | Q18: NO PARA LP | R18: 0 | S18: =IFERROR((MaestraLP3[[#This Row],[COSTO ]]/MaestraLP3[[#This Row],[COSTO OCT]]-1),0) -> 0 | T18: CALZADA | U18: CALZADA | V18: =+VLOOKUP(MaestraLP3[[#This Row],[-]],'[1]BD MES'!$A:$N,14,0) -> 12028 | W18: 15190 | X18: =+(MaestraLP3[[#This Row],[COSTO ]]-MaestraLP3[[#This Row],[COSTO OCT AL 27-10]])/MaestraLP3[[#This Row],[COSTO OCT AL 27-10]] -> 0.2628866 | Y18: =++IF(Q18="HASTA AGOTAR STOCK","HASTA AGOTAR STOCK",IF(MaestraLP3[[#This Row],[PRECIO OCT]]=0,"NO PARA LP",IF(MaestraLP3[[#This Row],[PRECIO OCT]]=0,"INCORPORACIÓN",IF(AA18=0,"MANTIENE",IF(AA18<0,"BAJA",IF(AA18>0,"ALZA","")))))) -> NO PARA LP | Z18: 0 | AA18: =IF(Z18=0,"INDICAR PRECIO VTA",Z18-MaestraLP3[[#This Row],[PRECIO OCT]]) -> INDICAR PRECIO VTA | AB18: =+IFERROR((Z18-W18)/Z18,"-") -> - | AC18: =IFERROR(MaestraLP3[[#This Row],[PRECIO]]*MaestraLP3[[#This Row],[%MG UMV]],0) -> 0 | AD18: 8.06 | AE18: =IFERROR(MaestraLP3[[#This Row],[MARGEN UNITARIO]]/MaestraLP3[[#This Row],[Peso Neto UMV (KG)]],0) -> 0 | AF18: NO | AG18: 1 | AH18: 0 | AI18: 0 | AK18: NO
A19: EXCLUSIVOS | B19: 104548510 | C19: =+MaestraLP3[[#This Row],[CÓDIGO]]&MaestraLP3[[#Headers],[-]]&MaestraLP3[[#This Row],[UMV]] -> 104548510-C20 | D19: =+MaestraLP3[[#This Row],[CÓDIGO]]&MaestraLP3[[#Headers],[FS00]] -> 104548510FS00 | E19: BERNARDITA UNDURRAGA | F19: BERNARDITA UNDURRAGA | G19: BOLLERIA | H19: PANES PARA HORNEAR | I19: PAN BATARD 440 G | J19: C20 | K19: UN | M19: =VLOOKUP(MaestraLP3[[#This Row],[UMV]],VALIDACIONES!J:L,3,0) -> Caja 20 Unidades | N19: CONGELADOS | O19: IFS | P19: 15580 | Q19: NO PARA LP | R19: 0 | S19: =IFERROR((MaestraLP3[[#This Row],[COSTO ]]/MaestraLP3[[#This Row],[COSTO OCT]]-1),0) -> 0 | T19: CALZADA | U19: CALZADA | V19: =+VLOOKUP(MaestraLP3[[#This Row],[-]],'[1]BD MES'!$A:$N,14,0) -> 12480 | W19: 15580 | X19: =+(MaestraLP3[[#This Row],[COSTO ]]-MaestraLP3[[#This Row],[COSTO OCT AL 27-10]])/MaestraLP3[[#This Row],[COSTO OCT AL 27-10]] -> 0.24839744 | Y19: =++IF(Q19="HASTA AGOTAR STOCK","HASTA AGOTAR STOCK",IF(MaestraLP3[[#This Row],[PRECIO OCT]]=0,"NO PARA LP",IF(MaestraLP3[[#This Row],[PRECIO OCT]]=0,"INCORPORACIÓN",IF(AA19=0,"MANTIENE",IF(AA19<0,"BAJA",IF(AA19>0,"ALZA","")))))) -> NO PARA LP | Z19: 0 | AA19: =IF(Z19=0,"INDICAR PRECIO VTA",Z19-MaestraLP3[[#This Row],[PRECIO OCT]]) -> INDICAR PRECIO VTA | AB19: =+IFERROR((Z19-W19)/Z19,"-") -> - | AC19: =IFERROR(MaestraLP3[[#This Row],[PRECIO]]*MaestraLP3[[#This Row],[%MG UMV]],0) -> 0 | AD19: 8.8 | AE19: =IFERROR(MaestraLP3[[#This Row],[MARGEN UNITARIO]]/MaestraLP3[[#This Row],[Peso Neto UMV (KG)]],0) -> 0 | AF19: NO | AG19: 1 | AH19: 0 | AI19: 0 | AK19: NO
A20: EXCLUSIVOS | B20: 104548500 | C20: =+MaestraLP3[[#This Row],[CÓDIGO]]&MaestraLP3[[#Headers],[-]]&MaestraLP3[[#This Row],[UMV]] -> 104548500-C20 | D20: =+MaestraLP3[[#This Row],[CÓDIGO]]&MaestraLP3[[#Headers],[FS00]] -> 104548500FS00 | E20: BERNARDITA UNDURRAGA | F20: BERNARDITA UNDURRAGA | G20: BOLLERIA | H20: PANES PARA HORNEAR | I20: PAN BATARD INTEGRAL 440 G | J20: C20 | K20: UN | M20: =VLOOKUP(MaestraLP3[[#This Row],[UMV]],VALIDACIONES!J:L,3,0) -> Caja 20 Unidades | N20: CONGELADOS | O20: IFS | P20: 18740 | Q20: NO PARA LP | R20: 0 | S20: =IFERROR((MaestraLP3[[#This Row],[COSTO ]]/MaestraLP3[[#This Row],[COSTO OCT]]-1),0) -> 0 | T20: CALZADA | U20: CALZADA | V20: =+VLOOKUP(MaestraLP3[[#This Row],[-]],'[1]BD MES'!$A:$N,14,0) -> 15980 | W20: 18740 | X20: =+(MaestraLP3[[#This Row],[COSTO ]]-MaestraLP3[[#This Row],[COSTO OCT AL 27-10]])/MaestraLP3[[#This Row],[COSTO OCT AL 27-10]] -> 0.17271589 | Y20: =++IF(Q20="HASTA AGOTAR STOCK","HASTA AGOTAR STOCK",IF(MaestraLP3[[#This Row],[PRECIO OCT]]=0,"NO PARA LP",IF(MaestraLP3[[#This Row],[PRECIO OCT]]=0,"INCORPORACIÓN",IF(AA20=0,"MANTIENE",IF(AA20<0,"BAJA",IF(AA20>0,"ALZA","")))))) -> NO PARA LP | Z20: 0 | AA20: =IF(Z20=0,"INDICAR PRECIO VTA",Z20-MaestraLP3[[#This Row],[PRECIO OCT]]) -> INDICAR PRECIO VTA | AB20: =+IFERROR((Z20-W20)/Z20,"-") -> - | AC20: =IFERROR(MaestraLP3[[#This Row],[PRECIO]]*MaestraLP3[[#This Row],[%MG UMV]],0) -> 0 | AD20: 8.8 | AE20: =IFERROR(MaestraLP3[[#This Row],[MARGEN UNITARIO]]/MaestraLP3[[#This Row],[Peso Neto UMV (KG)]],0) -> 0 | AF20: NO | AG20: 1 | AH20: 0 | AI20: 0 | AK20: NO
A21: EXCLUSIVOS | B21: 104548590 | C21: =+MaestraLP3[[#This Row],[CÓDIGO]]&MaestraLP3[[#Headers],[-]]&MaestraLP3[[#This Row],[UMV]] -> 104548590-C20 | D21: =+MaestraLP3[[#This Row],[CÓDIGO]]&MaestraLP3[[#Headers],[FS00]] -> 104548590FS00 | E21: BERNARDITA UNDURRAGA | F21: BERNARDITA UNDURRAGA | G21: BOLLERIA | H21: PANES PARA HORNEAR | I21: PAN BATARD MULTICEREAL 440 G | J21: C20 | K21: UN | M21: =VLOOKUP(MaestraLP3[[#This Row],[UMV]],VALIDACIONES!J:L,3,0) -> Caja 20 Unidades | N21: CONGELADOS | O21: IFS | P21: 20060 | Q21: NO PARA LP | R21: 0 | S21: =IFERROR((MaestraLP3[[#This Row],[COSTO ]]/MaestraLP3[[#This Row],[COSTO OCT]]-1),0) -> 0 | T21: CALZADA | U21: CALZADA | V21: =+VLOOKUP(MaestraLP3[[#This Row],[-]],'[1]BD MES'!$A:$N,14,0) -> 17300 | W21: 20060 | X21: =+(MaestraLP3[[#This Row],[COSTO ]]-MaestraLP3[[#This Row],[COSTO OCT AL 27-10]])/MaestraLP3[[#This Row],[COSTO OCT AL 27-10]] -> 0.15953757 | Y21: =++IF(Q21="HASTA AGOTAR STOCK","HASTA AGOTAR STOCK",IF(MaestraLP3[[#This Row],[PRECIO OCT]]=0,"NO PARA LP",IF(MaestraLP3[[#This Row],[PRECIO OCT]]=0,"INCORPORACIÓN",IF(AA21=0,"MANTIENE",IF(AA21<0,"BAJA",IF(AA21>0,"ALZA","")))))) -> NO PARA LP | Z21: 0 | AA21: =IF(Z21=0,"INDICAR PRECIO VTA",Z21-MaestraLP3[[#This Row],[PRECIO OCT]]) -> INDICAR PRECIO VTA | AB21: =+IFERROR((Z21-W21)/Z21,"-") -> - | AC21: =IFERROR(MaestraLP3[[#This Row],[PRECIO]]*MaestraLP3[[#This Row],[%MG UMV]],0) -> 0 | AD21: 8.8 | AE21: =IFERROR(MaestraLP3[[#This Row],[MARGEN UNITARIO]]/MaestraLP3[[#This Row],[Peso Neto UMV (KG)]],0) -> 0 | AF21: NO | AG21: 1 | AH21: 0 | AI21: 0 | AK21: NO
A22: EXCLUSIVOS | B22: 104548570 | C22: =+MaestraLP3[[#This Row],[CÓDIGO]]&MaestraLP3[[#Headers],[-]]&MaestraLP3[[#This Row],[UMV]] -> 104548570-C40 | D22: =+MaestraLP3[[#This Row],[CÓDIGO]]&MaestraLP3[[#Headers],[FS00]] -> 104548570FS00 | E22: BERNARDITA UNDURRAGA | F22: BERNARDITA UNDURRAGA | G22: BOLLERIA | H22: PANES PARA HORNEAR | I22: PAN CIABATTA 130 G | J22: C40 | K22: UN | M22: =VLOOKUP(MaestraLP3[[#This Row],[UMV]],VALIDACIONES!J:L,3,0) -> Caja 40 Unidades | N22: CONGELADOS | O22: IFS | P22: 12440 | Q22: NO PARA LP | R22: 0 | S22: =IFERROR((MaestraLP3[[#This Row],[COSTO ]]/MaestraLP3[[#This Row],[COSTO OCT]]-1),0) -> 0 | T22: ACTIVO | U22: ACTIVO | V22: =+VLOOKUP(MaestraLP3[[#This Row],[-]],'[1]BD MES'!$A:$N,14,0) -> 9760 | W22: 12440 | X22: =+(MaestraLP3[[#This Row],[COSTO ]]-MaestraLP3[[#This Row],[COSTO OCT AL 27-10]])/MaestraLP3[[#This Row],[COSTO OCT AL 27-10]] -> 0.27459016 | Y22: =++IF(Q22="HASTA AGOTAR STOCK","HASTA AGOTAR STOCK",IF(MaestraLP3[[#This Row],[PRECIO OCT]]=0,"NO PARA LP",IF(MaestraLP3[[#This Row],[PRECIO OCT]]=0,"INCORPORACIÓN",IF(AA22=0,"MANTIENE",IF(AA22<0,"BAJA",IF(AA22>0,"ALZA","")))))) -> NO PARA LP | Z22: 0 | AA22: =IF(Z22=0,"INDICAR PRECIO VTA",Z22-MaestraLP3[[#This Row],[PRECIO OCT]]) -> INDICAR PRECIO VTA | AB22: =+IFERROR((Z22-W22)/Z22,"-") -> - | AC22: =IFERROR(MaestraLP3[[#This Row],[PRECIO]]*MaestraLP3[[#This Row],[%MG UMV]],0) -> 0 | AD22: 5.2 | AE22: =IFERROR(MaestraLP3[[#This Row],[MARGEN UNITARIO]]/MaestraLP3[[#This Row],[Peso Neto UMV (KG)]],0) -> 0 | AF22: NO | AG22: 1 | AH22: 0 | AI22: 0 | AK22: NO
A23: EXCLUSIVOS | B23: 104548560 | C23: =+MaestraLP3[[#This Row],[CÓDIGO]]&MaestraLP3[[#Headers],[-]]&MaestraLP3[[#This Row],[UMV]] -> 104548560-C31 | D23: =+MaestraLP3[[#This Row],[CÓDIGO]]&MaestraLP3[[#Headers],[FS00]] -> 104548560FS00 | E23: BERNARDITA UNDURRAGA | F23: BERNARDITA UNDURRAGA | G23: BOLLERIA | H23: PANES PARA HORNEAR | I23: PAN CIABATTA GRANDE 300 G | J23: C31 | K23: UN | M23: =VLOOKUP(MaestraLP3[[#This Row],[UMV]],VALIDACIONES!J:L,3,0) -> Caja 31 Unidades | N23: CONGELADOS | O23: IFS | P23: 21886 | Q23: NO PARA LP | R23: 0 | S23: =IFERROR((MaestraLP3[[#This Row],[COSTO ]]/MaestraLP3[[#This Row],[COSTO OCT]]-1),0) -> 0 | T23: CALZADA | U23: CALZADA | V23: =+VLOOKUP(MaestraLP3[[#This Row],[-]],'[1]BD MES'!$A:$N,14,0) -> 19313 | W23: 21886 | X23: =+(MaestraLP3[[#This Row],[COSTO ]]-MaestraLP3[[#This Row],[COSTO OCT AL 27-10]])/MaestraLP3[[#This Row],[COSTO OCT AL 27-10]] -> 0.13322632 | Y23: =++IF(Q23="HASTA AGOTAR STOCK","HASTA AGOTAR STOCK",IF(MaestraLP3[[#This Row],[PRECIO OCT]]=0,"NO PARA LP",IF(MaestraLP3[[#This Row],[PRECIO OCT]]=0,"INCORPORACIÓN",IF(AA23=0,"MANTIENE",IF(AA23<0,"BAJA",IF(AA23>0,"ALZA","")))))) -> NO PARA LP | Z23: 22900 | AA23: =IF(Z23=0,"INDICAR PRECIO VTA",Z23-MaestraLP3[[#This Row],[PRECIO OCT]]) -> 22900 | AB23: =+IFERROR((Z23-W23)/Z23,"-") -> 0.044279476 | AC23: =IFERROR(MaestraLP3[[#This Row],[PRECIO]]*MaestraLP3[[#This Row],[%MG UMV]],0) -> 1014 | AD23: 9.3 | AE23: =IFERROR(MaestraLP3[[#This Row],[MARGEN UNITARIO]]/MaestraLP3[[#This Row],[Peso Neto UMV (KG)]],0) -> 109.03226 | AF23: NO | AG23: 1 | AH23: 0 | AI23: 0 | AK23: NO
A24: EXCLUSIVOS | B24: 104548550 | C24: =+MaestraLP3[[#This Row],[CÓDIGO]]&MaestraLP3[[#Headers],[-]]&MaestraLP3[[#This Row],[UMV]] -> 104548550-C20 | D24: =+MaestraLP3[[#This Row],[CÓDIGO]]&MaestraLP3[[#Headers],[FS00]] -> 104548550FS00 | E24: BERNARDITA UNDURRAGA | F24: BERNARDITA UNDURRAGA | G24: BOLLERIA | H24: PANES PARA HORNEAR | I24: PAN GRAND RUSTICA 340 G | J24: C20 | K24: UN | M24: =VLOOKUP(MaestraLP3[[#This Row],[UMV]],VALIDACIONES!J:L,3,0) -> Caja 20 Unidades | N24: CONGELADOS | O24: IFS | P24: 17680 | Q24: NO PARA LP | R24: 0 | S24: =IFERROR((MaestraLP3[[#This Row],[COSTO ]]/MaestraLP3[[#This Row],[COSTO OCT]]-1),0) -> 0 | T24: CALZADA | U24: CALZADA | V24: =+VLOOKUP(MaestraLP3[[#This Row],[-]],'[1]BD MES'!$A:$N,14,0) -> 17680 | W24: 17680 | X24: =+(MaestraLP3[[#This Row],[COSTO ]]-MaestraLP3[[#This Row],[COSTO OCT AL 27-10]])/MaestraLP3[[#This Row],[COSTO OCT AL 27-10]] -> 0 | Y24: =++IF(Q24="HASTA AGOTAR STOCK","HASTA AGOTAR STOCK",IF(MaestraLP3[[#This Row],[PRECIO OCT]]=0,"NO PARA LP",IF(MaestraLP3[[#This Row],[PRECIO OCT]]=0,"INCORPORACIÓN",IF(AA24=0,"MANTIENE",IF(AA24<0,"BAJA",IF(AA24>0,"ALZA","")))))) -> NO PARA LP | Z24: 0 | AA24: =IF(Z24=0,"INDICAR PRECIO VTA",Z24-MaestraLP3[[#This Row],[PRECIO OCT]]) -> INDICAR PRECIO VTA | AB24: =+IFERROR((Z24-W24)/Z24,"-") -> - | AC24: =IFERROR(MaestraLP3[[#This Row],[PRECIO]]*MaestraLP3[[#This Row],[%MG UMV]],0) -> 0 | AD24: 6.8 | AE24: =IFERROR(MaestraLP3[[#This Row],[MARGEN UNITARIO]]/MaestraLP3[[#This Row],[Peso Neto UMV (KG)]],0) -> 0 | AF24: NO | AG24: 1 | AH24: 0 | AI24: 0 | AK24: NO
... A40: EXCLUSIVOS | B40: 104548380 | C40: =+MaestraLP3[[#This Row],[CÓDIGO]]&MaestraLP3[[#Headers],[-]]&MaestraLP3[[#This Row],[UMV]] -> 104548380-V00 | D40: =+MaestraLP3[[#This Row],[CÓDIGO]]&MaestraLP3[[#Headers],[FS00]] -> 104548380FS00 | E40: MARÍA DE LOS ÁNGELES QUIRÓZ | F40: GIORGIO LEVA | G40: SUMINISTROS | H40: DESECHABLES | I40: POTE 12 OZ / 340 CC | J40: V00 | K40: UN | M40: =VLOOKUP(MaestraLP3[[#This Row],[UMV]],VALIDACIONES!J:L,3,0) -> Caja 500 Unidades | N40: SECO | O40: NFS | P40: 30000 | Q40: NO PARA LP | R40: 0 | S40: =IFERROR((MaestraLP3[[#This Row],[COSTO ]]/MaestraLP3[[#This Row],[COSTO OCT]]-1),0) -> 0 | T40: CALZADA | U40: CALZADA | V40: =+VLOOKUP(MaestraLP3[[#This Row],[-]],'[1]BD MES'!$A:$N,14,0) -> 30000 | W40: 30000 | X40: =+(MaestraLP3[[#This Row],[COSTO ]]-MaestraLP3[[#This Row],[COSTO OCT AL 27-10]])/MaestraLP3[[#This Row],[COSTO OCT AL 27-10]] -> 0 | Y40: =++IF(Q40="HASTA AGOTAR STOCK","HASTA AGOTAR STOCK",IF(MaestraLP3[[#This Row],[PRECIO OCT]]=0,"NO PARA LP",IF(MaestraLP3[[#This Row],[PRECIO OCT]]=0,"INCORPORACIÓN",IF(AA40=0,"MANTIENE",IF(AA40<0,"BAJA",IF(AA40>0,"ALZA","")))))) -> NO PARA LP | Z40: 0 | AA40: =IF(Z40=0,"INDICAR PRECIO VTA",Z40-MaestraLP3[[#This Row],[PRECIO OCT]]) -> INDICAR PRECIO VTA | AB40: =+IFERROR((Z40-W40)/Z40,"-") -> - | AC40: =IFERROR(MaestraLP3[[#This Row],[PRECIO]]*MaestraLP3[[#This Row],[%MG UMV]],0) -> 0 | AD40: 5 | AE40: =IFERROR(MaestraLP3[[#This Row],[MARGEN UNITARIO]]/MaestraLP3[[#This Row],[Peso Neto UMV (KG)]],0) -> 0 | AF40: NO | AG40: 1 | AH40: 0 | AI40: 0 | AK40: NO
A41: EXCLUSIVOS | B41: 104541910 | C41: =+MaestraLP3[[#This Row],[CÓDIGO]]&MaestraLP3[[#Headers],[-]]&MaestraLP3[[#This Row],[UMV]] -> 104541910-1Q | D41: =+MaestraLP3[[#This Row],[CÓDIGO]]&MaestraLP3[[#Headers],[FS00]] -> 104541910FS00 | E41: MARÍA DE LOS ÁNGELES QUIRÓZ | F41: GIORGIO LEVA | G41: SUMINISTROS | H41: DESECHABLES | I41: POTE P/KRAFT BLANCO PLA YOGEN FRUZ 16 OZ | J41: 1Q | K41: UN | M41: =VLOOKUP(MaestraLP3[[#This Row],[UMV]],VALIDACIONES!J:L,3,0) -> Caja 1000 Unidades | N41: SECO | O41: NFS | P41: 60000 | Q41: NO PARA LP | R41: 0 | S41: =IFERROR((MaestraLP3[[#This Row],[COSTO ]]/MaestraLP3[[#This Row],[COSTO OCT]]-1),0) -> 0 | T41: CALZADA | U41: CALZADA | V41: =+VLOOKUP(MaestraLP3[[#This Row],[-]],'[1]BD MES'!$A:$N,14,0) -> 60000 | W41: 60000 | X41: =+(MaestraLP3[[#This Row],[COSTO ]]-MaestraLP3[[#This Row],[COSTO OCT AL 27-10]])/MaestraLP3[[#This Row],[COSTO OCT AL 27-10]] -> 0 | Y41: =++IF(Q41="HASTA AGOTAR STOCK","HASTA AGOTAR STOCK",IF(MaestraLP3[[#This Row],[PRECIO OCT]]=0,"NO PARA LP",IF(MaestraLP3[[#This Row],[PRECIO OCT]]=0,"INCORPORACIÓN",IF(AA41=0,"MANTIENE",IF(AA41<0,"BAJA",IF(AA41>0,"ALZA","")))))) -> NO PARA LP | Z41: 0 | AA41: =IF(Z41=0,"INDICAR PRECIO VTA",Z41-MaestraLP3[[#This Row],[PRECIO OCT]]) -> INDICAR PRECIO VTA | AB41: =+IFERROR((Z41-W41)/Z41,"-") -> - | AC41: =IFERROR(MaestraLP3[[#This Row],[PRECIO]]*MaestraLP3[[#This Row],[%MG UMV]],0) -> 0 | AD41: 14 | AE41: =IFERROR(MaestraLP3[[#This Row],[MARGEN UNITARIO]]/MaestraLP3[[#This Row],[Peso Neto UMV (KG)]],0) -> 0 | AF41: NO | AG41: 1 | AH41: 0 | AI41: 0 | AJ41: SI | AK41: NO
A42: EXCLUSIVOS | B42: 104541920 | C42: =+MaestraLP3[[#This Row],[CÓDIGO]]&MaestraLP3[[#Headers],[-]]&MaestraLP3[[#This Row],[UMV]] -> 104541920-V00 | D42: =+MaestraLP3[[#This Row],[CÓDIGO]]&MaestraLP3[[#Headers],[FS00]] -> 104541920FS00 | E42: MARÍA DE LOS ÁNGELES QUIRÓZ | F42: GIORGIO LEVA | G42: SUMINISTROS | H42: DESECHABLES | I42: POTE P/KRAFT BLANCO PLA YOGEN FRUZ 24 OZ | J42: V00 | K42: UN | M42: =VLOOKUP(MaestraLP3[[#This Row],[UMV]],VALIDACIONES!J:L,3,0) -> Caja 500 Unidades | N42: SECO | O42: NFS | P42: 52500 | Q42: NO PARA LP | R42: 0 | S42: =IFERROR((MaestraLP3[[#This Row],[COSTO ]]/MaestraLP3[[#This Row],[COSTO OCT]]-1),0) -> 0 | T42: CALZADA | U42: CALZADA | V42: =+VLOOKUP(MaestraLP3[[#This Row],[-]],'[1]BD MES'!$A:$N,14,0) -> 52500 | W42: 52500 | X42: =+(MaestraLP3[[#This Row],[COSTO ]]-MaestraLP3[[#This Row],[COSTO OCT AL 27-10]])/MaestraLP3[[#This Row],[COSTO OCT AL 27-10]] -> 0 | Y42: =++IF(Q42="HASTA AGOTAR STOCK","HASTA AGOTAR STOCK",IF(MaestraLP3[[#This Row],[PRECIO OCT]]=0,"NO PARA LP",IF(MaestraLP3[[#This Row],[PRECIO OCT]]=0,"INCORPORACIÓN",IF(AA42=0,"MANTIENE",IF(AA42<0,"BAJA",IF(AA42>0,"ALZA","")))))) -> NO PARA LP | Z42: 0 | AA42: =IF(Z42=0,"INDICAR PRECIO VTA",Z42-MaestraLP3[[#This Row],[PRECIO OCT]]) -> INDICAR PRECIO VTA | AB42: =+IFERROR((Z42-W42)/Z42,"-") -> - | AC42: =IFERROR(MaestraLP3[[#This Row],[PRECIO]]*MaestraLP3[[#This Row],[%MG UMV]],0) -> 0 | AD42: 8.5 | AE42: =IFERROR(MaestraLP3[[#This Row],[MARGEN UNITARIO]]/MaestraLP3[[#This Row],[Peso Neto UMV (KG)]],0) -> 0 | AF42: NO | AG42: 1 | AH42: 0 | AI42: 0 | AJ42: SI | AK42: NO
A43: EXCLUSIVOS | B43: 104541900 | C43: =+MaestraLP3[[#This Row],[CÓDIGO]]&MaestraLP3[[#Headers],[-]]&MaestraLP3[[#This Row],[UMV]] -> 104541900-1Q | D43: =+MaestraLP3[[#This Row],[CÓDIGO]]&MaestraLP3[[#Headers],[FS00]] -> 104541900FS00 | E43: MARÍA DE LOS ÁNGELES QUIRÓZ | F43: GIORGIO LEVA | G43: SUMINISTROS | H43: DESECHABLES | I43: POTE P/KRAFT BLANCO PLA YOURSERV 12 OZ | J43: 1Q | K43: UN | M43: =VLOOKUP(MaestraLP3[[#This Row],[UMV]],VALIDACIONES!J:L,3,0) -> Caja 1000 Unidades | N43: SECO | O43: NFS | P43: 62000 | Q43: NO PARA LP | R43: 0 | S43: =IFERROR((MaestraLP3[[#This Row],[COSTO ]]/MaestraLP3[[#This Row],[COSTO OCT]]-1),0) -> 0 | T43: CALZADA | U43: CALZADA | V43: =+VLOOKUP(MaestraLP3[[#This Row],[-]],'[1]BD MES'!$A:$N,14,0) -> 62000 | W43: 62000 | X43: =+(MaestraLP3[[#This Row],[COSTO ]]-MaestraLP3[[#This Row],[COSTO OCT AL 27-10]])/MaestraLP3[[#This Row],[COSTO OCT AL 27-10]] -> 0 | Y43: =++IF(Q43="HASTA AGOTAR STOCK","HASTA AGOTAR STOCK",IF(MaestraLP3[[#This Row],[PRECIO OCT]]=0,"NO PARA LP",IF(MaestraLP3[[#This Row],[PRECIO OCT]]=0,"INCORPORACIÓN",IF(AA43=0,"MANTIENE",IF(AA43<0,"BAJA",IF(AA43>0,"ALZA","")))))) -> NO PARA LP | Z43: 0 | AA43: =IF(Z43=0,"INDICAR PRECIO VTA",Z43-MaestraLP3[[#This Row],[PRECIO OCT]]) -> INDICAR PRECIO VTA | AB43: =+IFERROR((Z43-W43)/Z43,"-") -> - | AC43: =IFERROR(MaestraLP3[[#This Row],[PRECIO]]*MaestraLP3[[#This Row],[%MG UMV]],0) -> 0 | AD43: 10 | AE43: =IFERROR(MaestraLP3[[#This Row],[MARGEN UNITARIO]]/MaestraLP3[[#This Row],[Peso Neto UMV (KG)]],0) -> 0 | AF43: NO | AG43: 1 | AH43: 0 | AI43: 0 | AJ43: SI | AK43: NO
A44: EXCLUSIVOS | B44: 104542540 | C44: =+MaestraLP3[[#This Row],[CÓDIGO]]&MaestraLP3[[#Headers],[-]]&MaestraLP3[[#This Row],[UMV]] -> 104542540-1Q | D44: =+MaestraLP3[[#This Row],[CÓDIGO]]&MaestraLP3[[#Headers],[FS00]] -> 104542540FS00 | E44: MARÍA DE LOS ÁNGELES QUIRÓZ | F44: GIORGIO LEVA | G44: SUMINISTROS | H44: DESECHABLES | I44: POTE PAPEL KRAFT BLANCO PLA FILIPPO 4 OZ | J44: 1Q | K44: UN | M44: =VLOOKUP(MaestraLP3[[#This Row],[UMV]],VALIDACIONES!J:L,3,0) -> Caja 1000 Unidades | N44: SECO | O44: NFS | P44: 44000 | Q44: NO PARA LP | R44: 0 | S44: =IFERROR((MaestraLP3[[#This Row],[COSTO ]]/MaestraLP3[[#This Row],[COSTO OCT]]-1),0) -> 0 | T44: CALZADA | U44: CALZADA | V44: =+VLOOKUP(MaestraLP3[[#This Row],[-]],'[1]BD MES'!$A:$N,14,0) -> 44000 | W44: 44000 | X44: =+(MaestraLP3[[#This Row],[COSTO ]]-MaestraLP3[[#This Row],[COSTO OCT AL 27-10]])/MaestraLP3[[#This Row],[COSTO OCT AL 27-10]] -> 0 | Y44: =++IF(Q44="HASTA AGOTAR STOCK","HASTA AGOTAR STOCK",IF(MaestraLP3[[#This Row],[PRECIO OCT]]=0,"NO PARA LP",IF(MaestraLP3[[#This Row],[PRECIO OCT]]=0,"INCORPORACIÓN",IF(AA44=0,"MANTIENE",IF(AA44<0,"BAJA",IF(AA44>0,"ALZA","")))))) -> NO PARA LP | Z44: 0 | AA44: =IF(Z44=0,"INDICAR PRECIO VTA",Z44-MaestraLP3[[#This Row],[PRECIO OCT]]) -> INDICAR PRECIO VTA | AB44: =+IFERROR((Z44-W44)/Z44,"-") -> - | AC44: =IFERROR(MaestraLP3[[#This Row],[PRECIO]]*MaestraLP3[[#This Row],[%MG UMV]],0) -> 0 | AD44: 6 | AE44: =IFERROR(MaestraLP3[[#This Row],[MARGEN UNITARIO]]/MaestraLP3[[#This Row],[Peso Neto UMV (KG)]],0) -> 0 | AF44: NO | AG44: 1 | AH44: 0 | AI44: 0 | AK44: NO
A45: EXCLUSIVOS | B45: 104548330 | C45: =+MaestraLP3[[#This Row],[CÓDIGO]]&MaestraLP3[[#Headers],[-]]&MaestraLP3[[#This Row],[UMV]] -> 104548330-X00 | D45: =+MaestraLP3[[#This Row],[CÓDIGO]]&MaestraLP3[[#Headers],[FS00]] -> 104548330FS00 | E45: MARÍA DE LOS ÁNGELES QUIRÓZ | F45: GIORGIO LEVA | G45: SUMINISTROS | H45: DESECHABLES | I45: TAPA BOWL 1300 CC / 185 MM | J45: X00 | K45: UN | M45: =VLOOKUP(MaestraLP3[[#This Row],[UMV]],VALIDACIONES!J:L,3,0) -> Caja 300 Unidades | N45: SECO | O45: NFS | P45: 22200 | Q45: NO PARA LP | R45: 0 | S45: =IFERROR((MaestraLP3[[#This Row],[COSTO ]]/MaestraLP3[[#This Row],[COSTO OCT]]-1),0) -> 0 | T45: CALZADA | U45: CALZADA | V45: =+VLOOKUP(MaestraLP3[[#This Row],[-]],'[1]BD MES'!$A:$N,14,0) -> 22200 | W45: 22200 | X45: =+(MaestraLP3[[#This Row],[COSTO ]]-MaestraLP3[[#This Row],[COSTO OCT AL 27-10]])/MaestraLP3[[#This Row],[COSTO OCT AL 27-10]] -> 0 | Y45: =++IF(Q45="HASTA AGOTAR STOCK","HASTA AGOTAR STOCK",IF(MaestraLP3[[#This Row],[PRECIO OCT]]=0,"NO PARA LP",IF(MaestraLP3[[#This Row],[PRECIO OCT]]=0,"INCORPORACIÓN",IF(AA45=0,"MANTIENE",IF(AA45<0,"BAJA",IF(AA45>0,"ALZA","")))))) -> NO PARA LP | Z45: 0 | AA45: =IF(Z45=0,"INDICAR PRECIO VTA",Z45-MaestraLP3[[#This Row],[PRECIO OCT]]) -> INDICAR PRECIO VTA | AB45: =+IFERROR((Z45-W45)/Z45,"-") -> - | AC45: =IFERROR(MaestraLP3[[#This Row],[PRECIO]]*MaestraLP3[[#This Row],[%MG UMV]],0) -> 0 | AD45: 3 | AE45: =IFERROR(MaestraLP3[[#This Row],[MARGEN UNITARIO]]/MaestraLP3[[#This Row],[Peso Neto UMV (KG)]],0) -> 0 | AF45: NO | AG45: 1 | AH45: 0 | AI45: 0 | AK45: NO
A46: EXCLUSIVOS | B46: 104548390 | C46: =+MaestraLP3[[#This Row],[CÓDIGO]]&MaestraLP3[[#Headers],[-]]&MaestraLP3[[#This Row],[UMV]] -> 104548390-X00 | D46: =+MaestraLP3[[#This Row],[CÓDIGO]]&MaestraLP3[[#Headers],[FS00]] -> 104548390FS00 | E46: MARÍA DE LOS ÁNGELES QUIRÓZ | F46: GIORGIO LEVA | G46: SUMINISTROS | H46: DESECHABLES | I46: TAPA BOWL PLA 750 ML / 148 MM | J46: X00 | K46: UN | M46: =VLOOKUP(MaestraLP3[[#This Row],[UMV]],VALIDACIONES!J:L,3,0) -> Caja 300 Unidades | N46: SECO | O46: NFS | P46: 14700 | Q46: NO PARA LP | R46: 0 | S46: =IFERROR((MaestraLP3[[#This Row],[COSTO ]]/MaestraLP3[[#This Row],[COSTO OCT]]-1),0) -> 0 | T46: CALZADA | U46: CALZADA | V46: =+VLOOKUP(MaestraLP3[[#This Row],[-]],'[1]BD MES'!$A:$N,14,0) -> 14700 | W46: 14700 | X46: =+(MaestraLP3[[#This Row],[COSTO ]]-MaestraLP3[[#This Row],[COSTO OCT AL 27-10]])/MaestraLP3[[#This Row],[COSTO OCT AL 27-10]] -> 0 | Y46: =++IF(Q46="HASTA AGOTAR STOCK","HASTA AGOTAR STOCK",IF(MaestraLP3[[#This Row],[PRECIO OCT]]=0,"NO PARA LP",IF(MaestraLP3[[#This Row],[PRECIO OCT]]=0,"INCORPORACIÓN",IF(AA46=0,"MANTIENE",IF(AA46<0,"BAJA",IF(AA46>0,"ALZA","")))))) -> NO PARA LP | Z46: 0 | AA46: =IF(Z46=0,"INDICAR PRECIO VTA",Z46-MaestraLP3[[#This Row],[PRECIO OCT]]) -> INDICAR PRECIO VTA | AB46: =+IFERROR((Z46-W46)/Z46,"-") -> - | AC46: =IFERROR(MaestraLP3[[#This Row],[PRECIO]]*MaestraLP3[[#This Row],[%MG UMV]],0) -> 0 | AD46: 3 | AE46: =IFERROR(MaestraLP3[[#This Row],[MARGEN UNITARIO]]/MaestraLP3[[#This Row],[Peso Neto UMV (KG)]],0) -> 0 | AF46: NO | AG46: 1 | AH46: 0 | AI46: 0 | AK46: NO
A47: EXCLUSIVOS | B47: 104542950 | C47: =+MaestraLP3[[#This Row],[CÓDIGO]]&MaestraLP3[[#Headers],[-]]&MaestraLP3[[#This Row],[UMV]] -> 104542950-1Q | D47: =+MaestraLP3[[#This Row],[CÓDIGO]]&MaestraLP3[[#Headers],[FS00]] -> 104542950FS00 | E47: MARÍA DE LOS ÁNGELES QUIRÓZ | F47: GIORGIO LEVA | G47: SUMINISTROS | H47: DESECHABLES | I47: TAPA DOMO PLA TRANSPARENTE 12/16 OZ | J47: 1Q | K47: UN | M47: =VLOOKUP(MaestraLP3[[#This Row],[UMV]],VALIDACIONES!J:L,3,0) -> Caja 1000 Unidades | N47: SECO | O47: NFS | P47: 37100 | Q47: NO PARA LP | R47: 0 | S47: =IFERROR((MaestraLP3[[#This Row],[COSTO ]]/MaestraLP3[[#This Row],[COSTO OCT]]-1),0) -> 0 | T47: CALZADA | U47: CALZADA | V47: =+VLOOKUP(MaestraLP3[[#This Row],[-]],'[1]BD MES'!$A:$N,14,0) -> 37100 | W47: 37100 | X47: =+(MaestraLP3[[#This Row],[COSTO ]]-MaestraLP3[[#This Row],[COSTO OCT AL 27-10]])/MaestraLP3[[#This Row],[COSTO OCT AL 27-10]] -> 0 | Y47: =++IF(Q47="HASTA AGOTAR STOCK","HASTA AGOTAR STOCK",IF(MaestraLP3[[#This Row],[PRECIO OCT]]=0,"NO PARA LP",IF(MaestraLP3[[#This Row],[PRECIO OCT]]=0,"INCORPORACIÓN",IF(AA47=0,"MANTIENE",IF(AA47<0,"BAJA",IF(AA47>0,"ALZA","")))))) -> NO PARA LP | Z47: 0 | AA47: =IF(Z47=0,"INDICAR PRECIO VTA",Z47-MaestraLP3[[#This Row],[PRECIO OCT]]) -> INDICAR PRECIO VTA | AB47: =+IFERROR((Z47-W47)/Z47,"-") -> - | AC47: =IFERROR(MaestraLP3[[#This Row],[PRECIO]]*MaestraLP3[[#This Row],[%MG UMV]],0) -> 0 | AD47: 4 | AE47: =IFERROR(MaestraLP3[[#This Row],[MARGEN UNITARIO]]/MaestraLP3[[#This Row],[Peso Neto UMV (KG)]],0) -> 0 | AF47: NO | AG47: 1 | AH47: 0.07 | AI47: 0.1 | AJ47: SI | AK47: NO
A48: EXCLUSIVOS | B48: 104542960 | C48: =+MaestraLP3[[#This Row],[CÓDIGO]]&MaestraLP3[[#Headers],[-]]&MaestraLP3[[#This Row],[UMV]] -> 104542960-1Q | D48: =+MaestraLP3[[#This Row],[CÓDIGO]]&MaestraLP3[[#Headers],[FS00]] -> 104542960FS00 | E48: MARÍA DE LOS ÁNGELES QUIRÓZ | F48: GIORGIO LEVA | G48: SUMINISTROS | H48: DESECHABLES | I48: TAPA PLANA PLA TRANSPARENTE 12/16 OZ | J48: 1Q | K48: UN | M48: =VLOOKUP(MaestraLP3[[#This Row],[UMV]],VALIDACIONES!J:L,3,0) -> Caja 1000 Unidades | N48: SECO | O48: NFS | P48: 33300 | Q48: NO PARA LP | R48: 0 | S48: =IFERROR((MaestraLP3[[#This Row],[COSTO ]]/MaestraLP3[[#This Row],[COSTO OCT]]-1),0) -> 0 | T48: CALZADA | U48: CALZADA | V48: =+VLOOKUP(MaestraLP3[[#This Row],[-]],'[1]BD MES'!$A:$N,14,0) -> 33300 | W48: 33300 | X48: =+(MaestraLP3[[#This Row],[COSTO ]]-MaestraLP3[[#This Row],[COSTO OCT AL 27-10]])/MaestraLP3[[#This Row],[COSTO OCT AL 27-10]] -> 0 | Y48: =++IF(Q48="HASTA AGOTAR STOCK","HASTA AGOTAR STOCK",IF(MaestraLP3[[#This Row],[PRECIO OCT]]=0,"NO PARA LP",IF(MaestraLP3[[#This Row],[PRECIO OCT]]=0,"INCORPORACIÓN",IF(AA48=0,"MANTIENE",IF(AA48<0,"BAJA",IF(AA48>0,"ALZA","")))))) -> NO PARA LP | Z48: 0 | AA48: =IF(Z48=0,"INDICAR PRECIO VTA",Z48-MaestraLP3[[#This Row],[PRECIO OCT]]) -> INDICAR PRECIO VTA | AB48: =+IFERROR((Z48-W48)/Z48,"-") -> - | AC48: =IFERROR(MaestraLP3[[#This Row],[PRECIO]]*MaestraLP3[[#This Row],[%MG UMV]],0) -> 0 | AD48: 3 | AE48: =IFERROR(MaestraLP3[[#This Row],[MARGEN UNITARIO]]/MaestraLP3[[#This Row],[Peso Neto UMV (KG)]],0) -> 0 | AF48: SI | AG48: 1 | AH48: -0.001 | AI48: 0.1 | AJ48: SI | AK48: NO
A49: EXCLUSIVOS | B49: 104548340 | C49: =+MaestraLP3[[#This Row],[CÓDIGO]]&MaestraLP3[[#Headers],[-]]&MaestraLP3[[#This Row],[UMV]] -> 104548340-V00 | D49: =+MaestraLP3[[#This Row],[CÓDIGO]]&MaestraLP3[[#Headers],[FS00]] -> 104548340FS00 | E49: MARÍA DE LOS ÁNGELES QUIRÓZ | F49: GIORGIO LEVA | G49: SUMINISTROS | H49: DESECHABLES | I49: TAPA POTE PLA 12 OZ /115 MM | J49: V00 | K49: UN | M49: =VLOOKUP(MaestraLP3[[#This Row],[UMV]],VALIDACIONES!J:L,3,0) -> Caja 500 Unidades | N49: SECO | O49: NFS | P49: 30000 | Q49: NO PARA LP | R49: 0 | S49: =IFERROR((MaestraLP3[[#This Row],[COSTO ]]/MaestraLP3[[#This Row],[COSTO OCT]]-1),0) -> 0 | T49: CALZADA | U49: CALZADA | V49: =+VLOOKUP(MaestraLP3[[#This Row],[-]],'[1]BD MES'!$A:$N,14,0) -> 30000 | W49: 30000 | X49: =+(MaestraLP3[[#This Row],[COSTO ]]-MaestraLP3[[#This Row],[COSTO OCT AL 27-10]])/MaestraLP3[[#This Row],[COSTO OCT AL 27-10]] -> 0 | Y49: =++IF(Q49="HASTA AGOTAR STOCK","HASTA AGOTAR STOCK",IF(MaestraLP3[[#This Row],[PRECIO OCT]]=0,"NO PARA LP",IF(MaestraLP3[[#This Row],[PRECIO OCT]]=0,"INCORPORACIÓN",IF(AA49=0,"MANTIENE",IF(AA49<0,"BAJA",IF(AA49>0,"ALZA","")))))) -> NO PARA LP | Z49: 0 | AA49: =IF(Z49=0,"INDICAR PRECIO VTA",Z49-MaestraLP3[[#This Row],[PRECIO OCT]]) -> INDICAR PRECIO VTA | AB49: =+IFERROR((Z49-W49)/Z49,"-") -> - | AC49: =IFERROR(MaestraLP3[[#This Row],[PRECIO]]*MaestraLP3[[#This Row],[%MG UMV]],0) -> 0 | AD49: 0.5 | AE49: =IFERROR(MaestraLP3[[#This Row],[MARGEN UNITARIO]]/MaestraLP3[[#This Row],[Peso Neto UMV (KG)]],0) -> 0 | AF49: NO | AG49: 1 | AH49: 0 | AI49: 0 | AK49: NO
A50: EXCLUSIVOS | B50: 104547120 | C50: =+MaestraLP3[[#This Row],[CÓDIGO]]&MaestraLP3[[#Headers],[-]]&MaestraLP3[[#This Row],[UMV]] -> 104547120-2Q | D50: =+MaestraLP3[[#This Row],[CÓDIGO]]&MaestraLP3[[#Headers],[FS00]] -> 104547120FS00 | E50: MARÍA DE LOS ÁNGELES QUIRÓZ | F50: GIORGIO LEVA | G50: SUMINISTROS | H50: DESECHABLES | I50: TAPA VASO 12 OZ PLATON | J50: 2Q | K50: UN | M50: =VLOOKUP(MaestraLP3[[#This Row],[UMV]],VALIDACIONES!J:L,3,0) -> Caja 2000 Unidades | N50: SECO | O50: NFS | P50: 44000 | Q50: NO PARA LP | R50: 0 | S50: =IFERROR((MaestraLP3[[#This Row],[COSTO ]]/MaestraLP3[[#This Row],[COSTO OCT]]-1),0) -> 0 | T50: CALZADA | U50: CALZADA | V50: =+VLOOKUP(MaestraLP3[[#This Row],[-]],'[1]BD MES'!$A:$N,14,0) -> 44000 | W50: 44000 | X50: =+(MaestraLP3[[#This Row],[COSTO ]]-MaestraLP3[[#This Row],[COSTO OCT AL 27-10]])/MaestraLP3[[#This Row],[COSTO OCT AL 27-10]] -> 0 | Y50: =++IF(Q50="HASTA AGOTAR STOCK","HASTA AGOTAR STOCK",IF(MaestraLP3[[#This Row],[PRECIO OCT]]=0,"NO PARA LP",IF(MaestraLP3[[#This Row],[PRECIO OCT]]=0,"INCORPORACIÓN",IF(AA50=0,"MANTIENE",IF(AA50<0,"BAJA",IF(AA50>0,"ALZA","")))))) -> NO PARA LP | Z50: 0 | AA50: =IF(Z50=0,"INDICAR PRECIO VTA",Z50-MaestraLP3[[#This Row],[PRECIO OCT]]) -> INDICAR PRECIO VTA | AB50: =+IFERROR((Z50-W50)/Z50,"-") -> - | AC50: =IFERROR(MaestraLP3[[#This Row],[PRECIO]]*MaestraLP3[[#This Row],[%MG UMV]],0) -> 0 | AD50: 6 | AE50: =IFERROR(MaestraLP3[[#This Row],[MARGEN UNITARIO]]/MaestraLP3[[#This Row],[Peso Neto UMV (KG)]],0) -> 0 | AF50: NO | AG50: 1 | AH50: 0 | AI50: 0 | AJ50: SI | AK50: NO
A51: EXCLUSIVOS | B51: 104547130 | C51: =+MaestraLP3[[#This Row],[CÓDIGO]]&MaestraLP3[[#Headers],[-]]&MaestraLP3[[#This Row],[UMV]] -> 104547130-2Q | D51: =+MaestraLP3[[#This Row],[CÓDIGO]]&MaestraLP3[[#Headers],[FS00]] -> 104547130FS00 | E51: MARÍA DE LOS ÁNGELES QUIRÓZ | F51: GIORGIO LEVA | G51: SUMINISTROS | H51: DESECHABLES | I51: TAPA VASO 21 OZ PLATON | J51: 2Q | K51: UN | M51: =VLOOKUP(MaestraLP3[[#This Row],[UMV]],VALIDACIONES!J:L,3,0) -> Caja 2000 Unidades | N51: SECO | O51: NFS | P51: 54000 | Q51: NO PARA LP | R51: 0 | S51: =IFERROR((MaestraLP3[[#This Row],[COSTO ]]/MaestraLP3[[#This Row],[COSTO OCT]]-1),0) -> 0 | T51: CALZADA | U51: CALZADA | V51: =+VLOOKUP(MaestraLP3[[#This Row],[-]],'[1]BD MES'!$A:$N,14,0) -> 54000 | W51: 54000 | X51: =+(MaestraLP3[[#This Row],[COSTO ]]-MaestraLP3[[#This Row],[COSTO OCT AL 27-10]])/MaestraLP3[[#This Row],[COSTO OCT AL 27-10]] -> 0 | Y51: =++IF(Q51="HASTA AGOTAR STOCK","HASTA AGOTAR STOCK",IF(MaestraLP3[[#This Row],[PRECIO OCT]]=0,"NO PARA LP",IF(MaestraLP3[[#This Row],[PRECIO OCT]]=0,"INCORPORACIÓN",IF(AA51=0,"MANTIENE",IF(AA51<0,"BAJA",IF(AA51>0,"ALZA","")))))) -> NO PARA LP | Z51: 0 | AA51: =IF(Z51=0,"INDICAR PRECIO VTA",Z51-MaestraLP3[[#This Row],[PRECIO OCT]]) -> INDICAR PRECIO VTA | AB51: =+IFERROR((Z51-W51)/Z51,"-") -> - | AC51: =IFERROR(MaestraLP3[[#This Row],[PRECIO]]*MaestraLP3[[#This Row],[%MG UMV]],0) -> 0 | AD51: 6 | AE51: =IFERROR(MaestraLP3[[#This Row],[MARGEN UNITARIO]]/MaestraLP3[[#This Row],[Peso Neto UMV (KG)]],0) -> 0 | AF51: NO | AG51: 1 | AH51: 0 | AI51: 0 | AJ51: SI | AK51: NO
A52: EXCLUSIVOS | B52: 104541950 | C52: =+MaestraLP3[[#This Row],[CÓDIGO]]&MaestraLP3[[#Headers],[-]]&MaestraLP3[[#This Row],[UMV]] -> 104541950-1Q | D52: =+MaestraLP3[[#This Row],[CÓDIGO]]&MaestraLP3[[#Headers],[FS00]] -> 104541950FS00 | E52: MARÍA DE LOS ÁNGELES QUIRÓZ | F52: GIORGIO LEVA | G52: SUMINISTROS | H52: DESECHABLES | I52: TAPA VASO PLA TRANSPARENTE 16 OZ | J52: 1Q | K52: UN | M52: =VLOOKUP(MaestraLP3[[#This Row],[UMV]],VALIDACIONES!J:L,3,0) -> Caja 1000 Unidades | N52: SECO | O52: NFS | P52: 31000 | Q52: NO PARA LP | R52: 0 | S52: =IFERROR((MaestraLP3[[#This Row],[COSTO ]]/MaestraLP3[[#This Row],[COSTO OCT]]-1),0) -> 0 | T52: CALZADA | U52: CALZADA | V52: =+VLOOKUP(MaestraLP3[[#This Row],[-]],'[1]BD MES'!$A:$N,14,0) -> 31000 | W52: 31000 | X52: =+(MaestraLP3[[#This Row],[COSTO ]]-MaestraLP3[[#This Row],[COSTO OCT AL 27-10]])/MaestraLP3[[#This Row],[COSTO OCT AL 27-10]] -> 0 | Y52: =++IF(Q52="HASTA AGOTAR STOCK","HASTA AGOTAR STOCK",IF(MaestraLP3[[#This Row],[PRECIO OCT]]=0,"NO PARA LP",IF(MaestraLP3[[#This Row],[PRECIO OCT]]=0,"INCORPORACIÓN",IF(AA52=0,"MANTIENE",IF(AA52<0,"BAJA",IF(AA52>0,"ALZA","")))))) -> NO PARA LP | Z52: 0 | AA52: =IF(Z52=0,"INDICAR PRECIO VTA",Z52-MaestraLP3[[#This Row],[PRECIO OCT]]) -> INDICAR PRECIO VTA | AB52: =+IFERROR((Z52-W52)/Z52,"-") -> - | AC52: =IFERROR(MaestraLP3[[#This Row],[PRECIO]]*MaestraLP3[[#This Row],[%MG UMV]],0) -> 0 | AD52: 4 | AE52: =IFERROR(MaestraLP3[[#This Row],[MARGEN UNITARIO]]/MaestraLP3[[#This Row],[Peso Neto UMV (KG)]],0) -> 0 | AF52: NO | AG52: 1 | AH52: 0.07 | AI52: 0.1 | AJ52: SI | AK52: NO
A53: EXCLUSIVOS | B53: 104548400 | C53: =+MaestraLP3[[#This Row],[CÓDIGO]]&MaestraLP3[[#Headers],[-]]&MaestraLP3[[#This Row],[UMV]] -> 104548400-1Q | D53: =+MaestraLP3[[#This Row],[CÓDIGO]]&MaestraLP3[[#Headers],[FS00]] -> 104548400FS00 | E53: MARÍA DE LOS ÁNGELES QUIRÓZ | F53: GIORGIO LEVA | G53: SUMINISTROS | H53: DESECHABLES | I53: TENEDOR PLA | J53: 1Q | K53: UN | M53: =VLOOKUP(MaestraLP3[[#This Row],[UMV]],VALIDACIONES!J:L,3,0) -> Caja 1000 Unidades | N53: SECO | O53: NFS | P53: 19000 | Q53: NO PARA LP | R53: 0 | S53: =IFERROR((MaestraLP3[[#This Row],[COSTO ]]/MaestraLP3[[#This Row],[COSTO OCT]]-1),0) -> 0 | T53: CALZADA | U53: CALZADA | V53: =+VLOOKUP(MaestraLP3[[#This Row],[-]],'[1]BD MES'!$A:$N,14,0) -> 19000 | W53: 19000 | X53: =+(MaestraLP3[[#This Row],[COSTO ]]-MaestraLP3[[#This Row],[COSTO OCT AL 27-10]])/MaestraLP3[[#This Row],[COSTO OCT AL 27-10]] -> 0 | Y53: =++IF(Q53="HASTA AGOTAR STOCK","HASTA AGOTAR STOCK",IF(MaestraLP3[[#This Row],[PRECIO OCT]]=0,"NO PARA LP",IF(MaestraLP3[[#This Row],[PRECIO OCT]]=0,"INCORPORACIÓN",IF(AA53=0,"MANTIENE",IF(AA53<0,"BAJA",IF(AA53>0,"ALZA","")))))) -> NO PARA LP | Z53: 0 | AA53: =IF(Z53=0,"INDICAR PRECIO VTA",Z53-MaestraLP3[[#This Row],[PRECIO OCT]]) -> INDICAR PRECIO VTA | AB53: =+IFERROR((Z53-W53)/Z53,"-") -> - | AC53: =IFERROR(MaestraLP3[[#This Row],[PRECIO]]*MaestraLP3[[#This Row],[%MG UMV]],0) -> 0 | AD53: 10 | AE53: =IFERROR(MaestraLP3[[#This Row],[MARGEN UNITARIO]]/MaestraLP3[[#This Row],[Peso Neto UMV (KG)]],0) -> 0 | AF53: NO | AG53: 1 | AH53: 0 | AI53: 0 | AK53: NO
A54: EXCLUSIVOS | B54: 104545260 | C54: =+MaestraLP3[[#This Row],[CÓDIGO]]&MaestraLP3[[#Headers],[-]]&MaestraLP3[[#This Row],[UMV]] -> 104545260-2Q | D54: =+MaestraLP3[[#This Row],[CÓDIGO]]&MaestraLP3[[#Headers],[FS00]] -> 104545260FS00 | E54: MARÍA DE LOS ÁNGELES QUIRÓZ | F54: GIORGIO LEVA | G54: SUMINISTROS | H54: DESECHABLES | I54: VASO 12 OZ PLATON | J54: 2Q | K54: UN | M54: =VLOOKUP(MaestraLP3[[#This Row],[UMV]],VALIDACIONES!J:L,3,0) -> Caja 2000 Unidades | N54: SECO | O54: NFS | P54: 66000 | Q54: NO PARA LP | R54: 0 | S54: =IFERROR((MaestraLP3[[#This Row],[COSTO ]]/MaestraLP3[[#This Row],[COSTO OCT]]-1),0) -> 0 | T54: CALZADA | U54: CALZADA | V54: =+VLOOKUP(MaestraLP3[[#This Row],[-]],'[1]BD MES'!$A:$N,14,0) -> 66000 | W54: 66000 | X54: =+(MaestraLP3[[#This Row],[COSTO ]]-MaestraLP3[[#This Row],[COSTO OCT AL 27-10]])/MaestraLP3[[#This Row],[COSTO OCT AL 27-10]] -> 0 | Y54: =++IF(Q54="HASTA AGOTAR STOCK","HASTA AGOTAR STOCK",IF(MaestraLP3[[#This Row],[PRECIO OCT]]=0,"NO PARA LP",IF(MaestraLP3[[#This Row],[PRECIO OCT]]=0,"INCORPORACIÓN",IF(AA54=0,"MANTIENE",IF(AA54<0,"BAJA",IF(AA54>0,"ALZA","")))))) -> NO PARA LP | Z54: 0 | AA54: =IF(Z54=0,"INDICAR PRECIO VTA",Z54-MaestraLP3[[#This Row],[PRECIO OCT]]) -> INDICAR PRECIO VTA | AB54: =+IFERROR((Z54-W54)/Z54,"-") -> - | AC54: =IFERROR(MaestraLP3[[#This Row],[PRECIO]]*MaestraLP3[[#This Row],[%MG UMV]],0) -> 0 | AD54: 14 | AE54: =IFERROR(MaestraLP3[[#This Row],[MARGEN UNITARIO]]/MaestraLP3[[#This Row],[Peso Neto UMV (KG)]],0) -> 0 | AF54: NO | AG54: 1 | AH54: 0 | AI54: 0 | AJ54: SI | AK54: NO
